Workbook

Sheet Legenda e Metodologia
A1: LEGENDA E METODOLOGIA — Aba "Indicadores"
A3: Esta aba explica como cada número da aba "Indicadores" é calculado e quais critérios foram usados, para que você possa auditar e ajustar quando precisar.
A5: Como funciona
A6: Todos os valores da aba "Indicadores" são fórmulas que buscam direto nas abas mensais (Janeiro 2026, Fevereiro 2026, etc.). Não digite números à mão nessa aba — se digitar, a fórmula é perdida.
A7: Quando você criar a aba de um novo mês (ex: "Setembro 2026"), copie a fórmula de um mês já pronto (ex: coluna I, referente a Agosto) para a coluna do novo mês e troque o nome da aba dentro da fórmula.
A8: Todas as fórmulas ignoram maiúsculas/minúsculas e espaços extras no início/fim do texto (TRIM/UPPER), para não quebrar por causa de digitação diferente.
A10: Indicadores excluídos a pedido do usuário
A11: "ASR irregular", "ASR negada" e "Total de protocolos SAC" NÃO foram incluídos, pois você indicou que não são calculados a partir desta base.
A13: Critério de cada indicador
A14: QUANTIDADE DE ASR PAGA (recebida): conta o número de linhas com "N° Solicitação" preenchido em cada mês.
A15: VALOR DE REEMBOLSO SOLICITADO / PAGO: soma as colunas "VALOR SOLICITADO" / "VALOR PAGO", apenas nas linhas com "N° Solicitação" preenchido (algumas abas mensais têm uma linha de subtotal solta, sem número de solicitação — essa linha é ignorada de propósito).
A16: BENEFICIÁRIOS COM REEMBOLSOS PAGOS: conta valores únicos (não vazios) da coluna "COD. DO BENEFICIÁRIO".
... A42: As fórmulas de SANTANDER R$ PAGO, ITAÚ R$ PAGO e PREMIUM FREE R$ (e as versões em quantidade) foram reescritas para não usar mais SOMARPRODUTO(CORRESP(...)) diretamente. Em vez disso, cada aba mensal ganhou uma coluna auxiliar "SEGMENTO" (coluna AC) que já classifica cada linha (SANTANDER / ITAU / PREMIUM FREE / vazio), e a aba Indicadores só soma/conta essa coluna com SOMASES/CONT.SES. Isso evita um comportamento do Excel (inserção automática do operador @) que fazia o SOMARPRODUTO somar só uma célula em vez da coluna inteira, gerando totais errados.

Sheet Códigos Santander (ref)
A1: CÓD. EMPRESA | B1: RAZÃO SOCIAL | D1: Fonte: arquivo "Santander_e_Itau_empresas.xlsx" (aba SANTANDER) enviado pela usuária em 21/09/2026 - lista de códigos de empresa do grupo Santander, usada nos indicadores "Santander R$ pago" e "Santander - Qtd ASR paga".
A2: 1RUGW | B2: BANCO SANTANDER BRASIL SA
A3: 0LDEA | B3: SUPER PAG ADM MEIOS ELETRONICOS SA
A4: 0KQ1R | B4: F1RST TECNOLOGIA E INOVACAO LTDA
A5: 0KGE5 | B5: BANCO SANTANDER BRASIL SA
A6: 0KRU9 | B6: SANB PROMOTORA DE VENDAS E COBRANCA SA
A7: 0KRUA | B7: SX TOOLS SOLUC SERV COMPARTILHADOS LTDA
A8: 1UX41 | B8: BANCO SANTANDER SA
A9: 1T5GA | B9: BANCO SANTANDER SA
A10: 1RUAW | B10: SANTANDER FINANCE ARRENDAMENTO MERCANTIL SA
A11: 1RUAY | B11: ATUAL SERVICOS RECUP DE CREDITOS E MEIOS DIGI
A12: 1RUAX | B12: ESFERA FIDELIDADE SA
A13: 1RUB0 | B13: BANCO SANTANDER BRASIL SA
... A40: 1RUF2 | B40: BANESPA SA CORRETORA DE CAMBIO E TITULOS
A41: 1RNXU
A42: 1RUF3 | B42: SANTANDER COMPANHIA SECUR DE CREDITOS FINANCE
A43: 1RUF4 | B43: AYMORE CREDITO FINANCIAMENTO E INVESTIMENTO S
A44: 1RUF5 | B44: REAL MICROCREDITO ASSESSORIA FINANCEIRA SA
A45: 1RU6Z | B45: F1RST TECNOLOGIA E INOVACAO LTDA
A46: 1RU70 | B46: SANTANDER SEC SERV BR DIST TIT VAL IMOB SA
A47: 1RU71 | B47: SANTANDER HOLDING IMOBILIARIA SA
A48: 1RU72 | B48: SANTANDER BRASIL TECNOLOGIA SA
A49: 1RU73 | B49: BANCO SANTANDER BRASIL SA
A50: 1RU74 | B50: SANTANDER BRASIL INVESTIMENTOS E SERVICOS SA
A51: 1RU75 | B51: BANCO SANTANDER BRASIL SA
A52: 1RU76 | B52: BANCO SANTANDER BRASIL SA
A53: 1RU77 | B53: SANTANDER BANESPA ASSET MANAGEMENT LTDA
... A79: S21FQ | B79: SANTANDER SERVICOS DIGITAIS BRASIL LTDA

Sheet Códigos Itaú (ref)
A1: CÓD. EMPRESA | B1: RAZÃO SOCIAL | D1: Fonte: arquivo "Santander_e_Itau_empresas.xlsx" (aba ITAU) enviado pela usuária em 21/09/2026 - lista de códigos de empresa do grupo Itaú, usada nos indicadores "Itaú R$ pago" e "Itaú - Qtd ASR paga" (substitui a busca por texto "ITAU" no nome da empresa).
A2: 1RSLN
A3: 1RSX6
A4: 1RT70
A5: 1RT73
A6: 1RT7A
A7: 1RU23
A8: 1RT8Z
A9: 1RT95
A10: 1RTSM
A11: 1RT1I
A12: 1RT1T
A13: 1RTAL
... A44: IMM5N

Sheet Indicadores
A1: QUANTIDADE DE ASR PAGA
A3: Mês | B3: Jan | C3: Fev | D3: Mar | E3: Abr | F3: Mai | G3: Jun | H3: Jul | I3: Ago | J3: Set | K3: Out | L3: Nov | M3: Dez | N3: Acumulado | O3: Média
A4: Ano
A5: ASR paga 2026 | B5: =COUNTA('Janeiro 2026'!$B$2:$B$3000) | C5: =COUNTA('Fevereiro 2026'!$B$2:$B$2999) | D5: =COUNTA('Março 2026'!$B$2:$B$2999) | E5: =COUNTA('Abril 2026 '!$B$2:$B$3000) | F5: =COUNTA('Maio 2026'!$B$2:$B$3000) | G5: =COUNTA('Junho 2026'!$B$2:$B$3000) | H5: =COUNTA('Julho 2026'!$B$2:$B$3000) | I5: =COUNTA('Agosto 2026'!$B$2:$B$3000) | J5: =COUNTA('Setembro 2026'!$B$2:$B$2998) | N5: =SUM(B5:M5) | O5: =IFERROR(AVERAGE(B5:M5),0)
A8: VALOR DE REEMBOLSO SOLICITADO (R$)
A10: Mês | B10: Jan | C10: Fev | D10: Mar | E10: Abr | F10: Mai | G10: Jun | H10: Jul | I10: Ago | J10: Set | K10: Out | L10: Nov | M10: Dez | N10: Acumulado | O10: Média
A11: Ano
A12: R$ solicitado 2026 | B12: =SUMIFS('Janeiro 2026'!$G$2:$G$3000,'Janeiro 2026'!$B$2:$B$3000,"<>") | C12: =SUMIFS('Fevereiro 2026'!$G$2:$G$2999,'Fevereiro 2026'!$B$2:$B$2999,"<>") | D12: =SUMIFS('Março 2026'!$G$2:$G$2999,'Março 2026'!$B$2:$B$2999,"<>") | E12: =SUMIFS('Abril 2026 '!$G$2:$G$3000,'Abril 2026 '!$B$2:$B$3000,"<>") | F12: =SUMIFS('Maio 2026'!$G$2:$G$3000,'Maio 2026'!$B$2:$B$3000,"<>") | G12: =SUMIFS('Junho 2026'!$G$2:$G$3000,'Junho 2026'!$B$2:$B$3000,"<>") | H12: =SUMIFS('Julho 2026'!$G$2:$G$3000,'Julho 2026'!$B$2:$B$3000,"<>") | I12: =SUMIFS('Agosto 2026'!$G$2:$G$3000,'Agosto 2026'!$B$2:$B$3000,"<>") | J12: =SUMIFS('Setembro 2026'!$G$2:$G$2998,'Setembro 2026'!$B$2:$B$2998,"<>") | N12: =SUM(B12:M12) | O12: =IFERROR(AVERAGE(B12:M12),0)
A15: VALOR DE REEMBOLSO PAGO (R$)
A17: Mês | B17: Jan | C17: Fev | D17: Mar | E17: Abr | F17: Mai | G17: Jun | H17: Jul | I17: Ago | J17: Set | K17: Out | L17: Nov | M17: Dez | N17: Acumulado | O17: Média
A18: Ano
A19: R$ pago 2026 | B19: =SUMIFS('Janeiro 2026'!$H$2:$H$3000,'Janeiro 2026'!$B$2:$B$3000,"<>") | C19: =SUMIFS('Fevereiro 2026'!$H$2:$H$2999,'Fevereiro 2026'!$B$2:$B$2999,"<>") | D19: =SUMIFS('Março 2026'!$H$2:$H$2999,'Março 2026'!$B$2:$B$2999,"<>") | E19: =SUMIFS('Abril 2026 '!$H$2:$H$3000,'Abril 2026 '!$B$2:$B$3000,"<>") | F19: =SUMIFS('Maio 2026'!$H$2:$H$3000,'Maio 2026'!$B$2:$B$3000,"<>") | G19: =SUMIFS('Junho 2026'!$H$2:$H$3000,'Junho 2026'!$B$2:$B$3000,"<>") | H19: =SUMIFS('Julho 2026'!$H$2:$H$3000,'Julho 2026'!$B$2:$B$3000,"<>") | I19: =SUMIFS('Agosto 2026'!$H$2:$H$3000,'Agosto 2026'!$B$2:$B$3000,"<>") | J19: =SUMIFS('Setembro 2026'!$H$2:$H$2998,'Setembro 2026'!$B$2:$B$2998,"<>") | N19: =SUM(B19:M19) | O19: =IFERROR(AVERAGE(B19:M19),0)
A22: QUANTIDADE DE BENEFICIÁRIOS COM REEMBOLSOS PAGOS
A24: Mês | B24: Jan | C24: Fev | D24: Mar | E24: Abr | F24: Mai | G24: Jun | H24: Jul | I24: Ago | J24: Set | K24: Out | L24: Nov | M24: Dez | N24: Acumulado | O24: Média
A25: Ano
A26: 2026 | B26: =SUMPRODUCT(('Janeiro 2026'!$F$2:$F$3000<>"")/COUNTIF('Janeiro 2026'!$F$2:$F$3000,'Janeiro 2026'!$F$2:$F$3000&"")) | C26: =SUMPRODUCT(('Fevereiro 2026'!$F$2:$F$2999<>"")/COUNTIF('Fevereiro 2026'!$F$2:$F$2999,'Fevereiro 2026'!$F$2:$F$2999&"")) | D26: =SUMPRODUCT(('Março 2026'!$F$2:$F$2999<>"")/COUNTIF('Março 2026'!$F$2:$F$2999,'Março 2026'!$F$2:$F$2999&"")) | E26: =SUMPRODUCT(('Abril 2026 '!$F$2:$F$3000<>"")/COUNTIF('Abril 2026 '!$F$2:$F$3000,'Abril 2026 '!$F$2:$F$3000&"")) | F26: =SUMPRODUCT(('Maio 2026'!$F$2:$F$3000<>"")/COUNTIF('Maio 2026'!$F$2:$F$3000,'Maio 2026'!$F$2:$F$3000&"")) | G26: =SUMPRODUCT(('Junho 2026'!$F$2:$F$3000<>"")/COUNTIF('Junho 2026'!$F$2:$F$3000,'Junho 2026'!$F$2:$F$3000&"")) | H26: =SUMPRODUCT(('Julho 2026'!$F$2:$F$3000<>"")/COUNTIF('Julho 2026'!$F$2:$F$3000,'Julho 2026'!$F$2:$F$3000&"")) | I26: {=SUMPRODUCT(('Agosto 2026'!$F$2:$F$3000<>"")/COUNTIF('Agosto 2026'!$F$2:$F$3000,'Agosto 2026'!$F$2:$F$3000&""))} | J26: {=SUMPRODUCT(('Setembro 2026'!$F$2:$F$2998<>"")/COUNTIF('Setembro 2026'!$F$2:$F$2998,'Setembro 2026'!$F$2:$F$2998&""))} | N26: =SUM(B26:M26) | O26: =IFERROR(AVERAGE(B26:M26),0)
A29: EMPRESAS COM MAIORES VALORES (R$) DE REEMBOLSO + PRODUTO PREMIUM FREE
A31: Mês | B31: Jan | C31: Fev | D31: Mar | E31: Abr | F31: Mai | G31: Jun | H31: Jul | I31: Ago | J31: Set | K31: Out | L31: Nov | M31: Dez | N31: Acumulado | O31: Média
A32: Empresas
A33: Santander R$ pago 2026 | B33: =SUMIFS('Janeiro 2026'!$H$2:$H$5000,'Janeiro 2026'!$AC$2:$AC$5000,"SANTANDER") | C33: =SUMIFS('Fevereiro 2026'!$H$2:$H$5000,'Fevereiro 2026'!$AC$2:$AC$5000,"SANTANDER") | D33: =SUMIFS('Março 2026'!$H$2:$H$5000,'Março 2026'!$AC$2:$AC$5000,"SANTANDER") | E33: =SUMIFS('Abril 2026 '!$H$2:$H$5000,'Abril 2026 '!$AC$2:$AC$5000,"SANTANDER") | F33: =SUMIFS('Maio 2026'!$H$2:$H$5000,'Maio 2026'!$AC$2:$AC$5000,"SANTANDER") | G33: =SUMIFS('Junho 2026'!$H$2:$H$5000,'Junho 2026'!$AC$2:$AC$5000,"SANTANDER") | H33: =SUMIFS('Julho 2026'!$H$2:$H$5000,'Julho 2026'!$AC$2:$AC$5000,"SANTANDER") | I33: =SUMIFS('Agosto 2026'!$H$2:$H$5000,'Agosto 2026'!$AC$2:$AC$5000,"SANTANDER") | J33: =SUMIFS('Setembro 2026'!$H$2:$H$5000,'Setembro 2026'!$AC$2:$AC$5000,"SANTANDER") | N33: =SUM(B33:M33) | O33: =IFERROR(AVERAGE(B33:M33),0)
A34: Itaú R$ pago 2026 | B34: =SUMIFS('Janeiro 2026'!$H$2:$H$5000,'Janeiro 2026'!$AC$2:$AC$5000,"ITAU") | C34: =SUMIFS('Fevereiro 2026'!$H$2:$H$5000,'Fevereiro 2026'!$AC$2:$AC$5000,"ITAU") | D34: =SUMIFS('Março 2026'!$H$2:$H$5000,'Março 2026'!$AC$2:$AC$5000,"ITAU") | E34: =SUMIFS('Abril 2026 '!$H$2:$H$5000,'Abril 2026 '!$AC$2:$AC$5000,"ITAU") | F34: =SUMIFS('Maio 2026'!$H$2:$H$5000,'Maio 2026'!$AC$2:$AC$5000,"ITAU") | G34: =SUMIFS('Junho 2026'!$H$2:$H$5000,'Junho 2026'!$AC$2:$AC$5000,"ITAU") | H34: =SUMIFS('Julho 2026'!$H$2:$H$5000,'Julho 2026'!$AC$2:$AC$5000,"ITAU") | I34: =SUMIFS('Agosto 2026'!$H$2:$H$5000,'Agosto 2026'!$AC$2:$AC$5000,"ITAU") | J34: =SUMIFS('Setembro 2026'!$H$2:$H$5000,'Setembro 2026'!$AC$2:$AC$5000,"ITAU") | N34: =SUM(B34:M34) | O34: =IFERROR(AVERAGE(B34:M34),0)
A35: Premium free R$ 2026 | B35: =SUMIFS('Janeiro 2026'!$H$2:$H$5000,'Janeiro 2026'!$AC$2:$AC$5000,"PREMIUM FREE") | C35: =SUMIFS('Fevereiro 2026'!$H$2:$H$5000,'Fevereiro 2026'!$AC$2:$AC$5000,"PREMIUM FREE") | D35: =SUMIFS('Março 2026'!$H$2:$H$5000,'Março 2026'!$AC$2:$AC$5000,"PREMIUM FREE") | E35: =SUMIFS('Abril 2026 '!$H$2:$H$5000,'Abril 2026 '!$AC$2:$AC$5000,"PREMIUM FREE") | F35: =SUMIFS('Maio 2026'!$H$2:$H$5000,'Maio 2026'!$AC$2:$AC$5000,"PREMIUM FREE") | G35: =SUMIFS('Junho 2026'!$H$2:$H$5000,'Junho 2026'!$AC$2:$AC$5000,"PREMIUM FREE") | H35: =SUMIFS('Julho 2026'!$H$2:$H$5000,'Julho 2026'!$AC$2:$AC$5000,"PREMIUM FREE") | I35: =SUMIFS('Agosto 2026'!$H$2:$H$5000,'Agosto 2026'!$AC$2:$AC$5000,"PREMIUM FREE") | J35: =SUMIFS('Setembro 2026'!$H$2:$H$5000,'Setembro 2026'!$AC$2:$AC$5000,"PREMIUM FREE") | N35: =SUM(B35:M35) | O35: =IFERROR(AVERAGE(B35:M35),0)
A38: ASRs PAGAS DENTRO DO PRAZO CONTRATUAL
A40: Mês | B40: Jan | C40: Fev | D40: Mar | E40: Abr | F40: Mai | G40: Jun | H40: Jul | I40: Ago | J40: Set | K40: Out | L40: Nov | M40: Dez | N40: Acumulado | O40: Média
A41: Ano
A42: ASRs dentro do prazo 2026 | B42: =SUMPRODUCT((TRIM(UPPER('Janeiro 2026'!$Y$2:$Y$3000))="SIM")*1) | C42: =SUMPRODUCT((TRIM(UPPER('Fevereiro 2026'!$Y$2:$Y$2999))="SIM")*1) | D42: =SUMPRODUCT((TRIM(UPPER('Março 2026'!$Y$2:$Y$2999))="SIM")*1) | E42: =SUMPRODUCT((TRIM(UPPER('Abril 2026 '!$Y$2:$Y$3000))="SIM")*1) | F42: =SUMPRODUCT((TRIM(UPPER('Maio 2026'!$Y$2:$Y$3000))="SIM")*1) | G42: =SUMPRODUCT((TRIM(UPPER('Junho 2026'!$Y$2:$Y$3000))="SIM")*1) | H42: {=SUMPRODUCT((TRIM(UPPER('Julho 2026'!$Y$2:$Y$3000))="SIM")*1)} | I42: {=SUMPRODUCT((TRIM(UPPER('Agosto 2026'!$Y$2:$Y$3000))="SIM")*1)} | J42: {=SUMPRODUCT((TRIM(UPPER('Setembro 2026'!$Y$2:$Y$2998))="SIM")*1)} | N42: =SUM(B42:M42)
A43: % sobre ASR recebida no mês | B43: =IFERROR(B42/B$5,"") | C43: =IFERROR(C42/C$5,"") | D43: =IFERROR(D42/D$5,"") | E43: =IFERROR(E42/E$5,"") | F43: =IFERROR(F42/F$5,"") | G43: =IFERROR(G42/G$5,"") | H43: =IFERROR(H42/H$5,"") | I43: =IFERROR(I42/I$5,"") | J43: =IFERROR(J42/J$5,"")
A45: ASRs PAGAS FORA DO PRAZO CONTRATUAL
A47: Mês | B47: Jan | C47: Fev | D47: Mar | E47: Abr | F47: Mai | G47: Jun | H47: Jul | I47: Ago | J47: Set | K47: Out | L47: Nov | M47: Dez | N47: Acumulado | O47: Média
A48: Ano
A49: ASRs fora do prazo 2026 | B49: =SUMPRODUCT((TRIM(UPPER('Janeiro 2026'!$Y$2:$Y$3000))="NÃO")*1) | C49: =SUMPRODUCT((TRIM(UPPER('Fevereiro 2026'!$Y$2:$Y$2999))="NÃO")*1) | D49: =SUMPRODUCT((TRIM(UPPER('Março 2026'!$Y$2:$Y$2999))="NÃO")*1) | E49: =SUMPRODUCT((TRIM(UPPER('Abril 2026 '!$Y$2:$Y$3000))="NÃO")*1) | F49: =SUMPRODUCT((TRIM(UPPER('Maio 2026'!$Y$2:$Y$3000))="NÃO")*1) | G49: =SUMPRODUCT((TRIM(UPPER('Junho 2026'!$Y$2:$Y$3000))="NÃO")*1) | H49: {=SUMPRODUCT((TRIM(UPPER('Julho 2026'!$Y$2:$Y$3000))="NÃO")*1)} | I49: {=SUMPRODUCT((TRIM(UPPER('Agosto 2026'!$Y$2:$Y$3000))="NÃO")*1)} | J49: {=SUMPRODUCT((TRIM(UPPER('Setembro 2026'!$Y$2:$Y$3000))="NÃO")*1)} | N49: =SUM(B49:M49)
A50: % sobre ASR recebida no mês | B50: =IFERROR(B49/B$5,"") | C50: =IFERROR(C49/C$5,"") | D50: =IFERROR(D49/D$5,"") | E50: =IFERROR(E49/E$5,"") | F50: =IFERROR(F49/F$5,"") | G50: =IFERROR(G49/G$5,"") | H50: =IFERROR(H49/H$5,"") | I50: =IFERROR(I49/I$5,"") | J50: =IFERROR(J49/J$5,"")
A52: SOLICITAÇÃO DE CADASTRO ASTREIN (DADOS BANCÁRIOS)
A54: Mês | B54: Jan | C54: Fev | D54: Mar | E54: Abr | F54: Mai | G54: Jun | H54: Jul | I54: Ago | J54: Set | K54: Out | L54: Nov | M54: Dez | N54: Acumulado | O54: Média
A55: Ano
A56: Ano 2026 | B56: =SUMPRODUCT((TRIM('Janeiro 2026'!$O$2:$O$3000)<>"")*(TRIM(UPPER('Janeiro 2026'!$O$2:$O$3000))<>"JA POSSUI")) | C56: =SUMPRODUCT((TRIM('Fevereiro 2026'!$O$2:$O$2999)<>"")*(TRIM(UPPER('Fevereiro 2026'!$O$2:$O$2999))<>"JA POSSUI")) | D56: =SUMPRODUCT((TRIM('Março 2026'!$O$2:$O$2999)<>"")*(TRIM(UPPER('Março 2026'!$O$2:$O$2999))<>"JA POSSUI")) | E56: =SUMPRODUCT((TRIM('Abril 2026 '!$O$2:$O$3000)<>"")*(TRIM(UPPER('Abril 2026 '!$O$2:$O$3000))<>"JA POSSUI")) | F56: =SUMPRODUCT((TRIM('Maio 2026'!$O$2:$O$3000)<>"")*(TRIM(UPPER('Maio 2026'!$O$2:$O$3000))<>"JA POSSUI")) | G56: =SUMPRODUCT((TRIM('Junho 2026'!$O$2:$O$3000)<>"")*(TRIM(UPPER('Junho 2026'!$O$2:$O$3000))<>"JA POSSUI")) | H56: {=SUMPRODUCT((TRIM('Julho 2026'!$O$2:$O$3000)<>"")*(TRIM(UPPER('Julho 2026'!$O$2:$O$3000))<>"JA POSSUI"))} | I56: {=SUMPRODUCT((TRIM('Agosto 2026'!$O$2:$O$3000)<>"")*(TRIM(UPPER('Agosto 2026'!$O$2:$O$3000))<>"JA POSSUI"))} | J56: {=SUMPRODUCT((TRIM('Setembro 2026'!$O$2:$O$2998)<>"")*(TRIM(UPPER('Setembro 2026'!$O$2:$O$2998))<>"JA POSSUI"))} | N56: =SUM(B56:M56) | O56: =IFERROR(AVERAGE(B56:M56),0)
A59: REEMBOLSO INSUFICIÊNCIA DE REDE EM R$
A61: Mês | B61: Jan | C61: Fev | D61: Mar | E61: Abr | F61: Mai | G61: Jun | H61: Jul | I61: Ago | J61: Set | K61: Out | L61: Nov | M61: Dez | N61: Acumulado | O61: Média
A62: Ano
A63: Ano 2026 | B63: =SUMIFS('Janeiro 2026'!$H$2:$H$5000,'Janeiro 2026'!$I$2:$I$5000,"*INSUFICIÊNCIA DE REDE*") | C63: =SUMIFS('Fevereiro 2026'!$H$2:$H$5000,'Fevereiro 2026'!$I$2:$I$5000,"*INSUFICIÊNCIA DE REDE*") | D63: =SUMIFS('Março 2026'!$H$2:$H$5000,'Março 2026'!$I$2:$I$5000,"*INSUFICIÊNCIA DE REDE*") | E63: =SUMIFS('Abril 2026 '!$H$2:$H$5000,'Abril 2026 '!$I$2:$I$5000,"*INSUFICIÊNCIA DE REDE*") | F63: =SUMIFS('Maio 2026'!$H$2:$H$5000,'Maio 2026'!$I$2:$I$5000,"*INSUFICIÊNCIA DE REDE*") | G63: =SUMIFS('Junho 2026'!$H$2:$H$5000,'Junho 2026'!$I$2:$I$5000,"*INSUFICIÊNCIA DE REDE*") | H63: =SUMIFS('Julho 2026'!$H$2:$H$5000,'Julho 2026'!$I$2:$I$5000,"*INSUFICIÊNCIA DE REDE*") | I63: =SUMIFS('Agosto 2026'!$H$2:$H$5000,'Agosto 2026'!$I$2:$I$5000,"*INSUFICIÊNCIA DE REDE*") | J63: =SUMIFS('Setembro 2026'!$H$2:$H$5000,'Setembro 2026'!$I$2:$I$5000,"*INSUFICIÊNCIA DE REDE*") | N63: =SUM(B63:M63) | O63: =IFERROR(AVERAGE(B63:M63),0)
...

Sheet Painel de Indicadores
A1: PAINEL DE INDICADORES DE REEMBOLSO (ASR) | R1: Dados-fonte do painel (ligados à aba "Indicadores" - não precisa mexer aqui)
A2: Auditoria Odontológica · Base 2026 · atualizado automaticamente a partir da aba "Indicadores"
R3: Motivo | S3: Valor 2026 (R$)
A4: ASR PAGA (ACUMULADO 2026) | E4: VALOR PAGO (ACUMULADO 2026) | I4: % DENTRO DO PRAZO CONTRATUAL | M4: TICKET MÉDIO PAGO (R$) | R4: Insuficiência de Rede | S4: ='Indicadores'!N63
A5: ='Indicadores'!N5 | E5: ='Indicadores'!N19 | I5: ='Indicadores'!N42/'Indicadores'!N5 | M5: ='Indicadores'!N19/'Indicadores'!N5 | R5: Cobrança Indevida | S5: ='Indicadores'!N70
R6: Deslocamento | S6: ='Indicadores'!N77
A7: ="Média mensal: "&TEXT('Indicadores'!O5,"#,##0")&" ASR/mês" | E7: ="Solicitado: R$ "&TEXT('Indicadores'!N12,"#,##0") | I7: ="Fora do prazo: "&TEXT('Indicadores'!N49,"#,##0")&" ASR" | M7: ="Beneficiários (soma mensal): "&TEXT('Indicadores'!N26,"#,##0")
A9: DISTRIBUIÇÃO E TENDÊNCIAS — 2026 | R9: Segmento | S9: Valor 2026 (R$)
R10: Santander | S10: ='Indicadores'!N33
R11: Itaú | S11: ='Indicadores'!N34
R12: Premium Free | S12: ='Indicadores'!N35
R13: Outros | S13: ='Indicadores'!N19-S10-S11-S12
R16: Mês | S16: ASR paga
R17: ='Indicadores'!B3 | S17: ='Indicadores'!B5
R18: ='Indicadores'!C3 | S18: ='Indicadores'!C5
R19: ='Indicadores'!D3 | S19: ='Indicadores'!D5
R20: ='Indicadores'!E3 | S20: ='Indicadores'!E5
R21: ='Indicadores'!F3 | S21: ='Indicadores'!F5
R22: ='Indicadores'!G3 | S22: ='Indicadores'!G5
R23: ='Indicadores'!H3 | S23: ='Indicadores'!H5
R24: ='Indicadores'!I3 | S24: ='Indicadores'!I5
R25: ='Indicadores'!J3 | S25: ='Indicadores'!J5
R28: Mês | S28: Dentro do prazo | T28: Fora do prazo
R29: ='Indicadores'!B3 | S29: ='Indicadores'!B42 | T29: ='Indicadores'!B49
R30: ='Indicadores'!C3 | S30: ='Indicadores'!C42 | T30: ='Indicadores'!C49
R31: ='Indicadores'!D3 | S31: ='Indicadores'!D42 | T31: ='Indicadores'!D49
R32: ='Indicadores'!E3 | S32: ='Indicadores'!E42 | T32: ='Indicadores'!E49
R33: ='Indicadores'!F3 | S33: ='Indicadores'!F42 | T33: ='Indicadores'!F49
R34: ='Indicadores'!G3 | S34: ='Indicadores'!G42 | T34: ='Indicadores'!G49
R35: ='Indicadores'!H3 | S35: ='Indicadores'!H42 | T35: ='Indicadores'!H49
R36: ='Indicadores'!I3 | S36: ='Indicadores'!I42 | T36: ='Indicadores'!I49
R37: ='Indicadores'!J3 | S37: ='Indicadores'!J42 | T37: ='Indicadores'!J49

Sheet Janeiro 2026
A1: CANAL | B1: N° SOLICITAÇÃO | C1: CÓD. EMPRESA | D1: EMPRESA | E1: CPF TITULAR | F1: COD. DO BENEFICIÁRIO | G1: VALOR SOLICITADO | H1: VALOR PAGO | I1: MOTIVO | J1: CPF/CNPJ DENTISTA | K1: NOME PRESTADOR DE SERVIÇO | L1: CIDADE PRESTADOR | M1: UF PRESTADOR | N1: AUDITOR | O1: ASTREIN | P1: DT SOLICITAÇÃO ASTREIN | Q1: DT LIBERAÇÃO ASTREIN | R1: STATUS DA SOLICITAÇÃO | S1: PROCESSO | T1: PRAZO CONTRATUAL | U1: DT AUDITORIA | V1: DT APROVAÇÃO | W1: DT PRAZO CONTRATUAL | X1: DATA DE PAGAMENTO SAP | Y1: PRAZO ATENDIDO | Z1: OBS | AC1: SEGMENTO (auxiliar automático)
A2: TELA | B2: 52406 | C2: 1RU51 | D2: BANCO SANTANDER BRASIL SA | E2: 8898809808 | F2: 1RU51000478008 | G2: 950 | H2: 391.95 | I2: CONTRATUAL | J2: 24870458000160 | K2: EDWAL LOBOSCHI | L2: SÃO PAULO | M2: SP | N2: SERGIANA | O2: 519338 | P2: 46014 | Q2: 46020 | R2: AUTORIZADO PAGAMENTO | S2: 8202610637 | T2: 5 DIAS ÚTEIS | U2: 46014 | V2: 46027 | W2: 46034 | X2: 46031 | Y2: =IF(AND(X2<>"",W2<>""),IF(X2<=W2,"SIM","NÃO"),"") | AC2: =IF($C2="","",IF(COUNTIF('Códigos Santander (ref)'!$A$2:$A$79,$C2)>0,"SANTANDER",IF(COUNTIF('Códigos Itaú (ref)'!$A$2:$A$44,$C2)>0,"ITAU",IF(AND(TRIM(UPPER($I2))="CONTRATUAL",ISNUMBER(SEARCH("INDIVIDUAL",SUBSTITUTE(UPPER($D2)," ","")))),"PREMIUM FREE",""))))
A3: TELA | B3: 52332 | C3: 1RUH3 | D3: BANCO SANTANDER BRASIL SA | E3: 35769531835 | F3: 1RUH3011824000 | G3: 1510 | H3: 290.45 | I3: CONTRATUAL | J3: 37709145892 | K3: FLAVIA MARTINS LEAL SEPINHO | L3: JACAREI | M3: SP | N3: SERGIANA | O3: 519341 | P3: 46014 | Q3: 46020 | R3: AUTORIZADO PAGAMENTO | S3: 8202610641 | T3: 5 DIAS ÚTEIS | U3: 46014 | V3: 46027 | W3: 46034 | X3: 46031 | Y3: =IF(AND(X3<>"",W3<>""),IF(X3<=W3,"SIM","NÃO"),"") | AC3: =IF($C3="","",IF(COUNTIF('Códigos Santander (ref)'!$A$2:$A$79,$C3)>0,"SANTANDER",IF(COUNTIF('Códigos Itaú (ref)'!$A$2:$A$44,$C3)>0,"ITAU",IF(AND(TRIM(UPPER($I3))="CONTRATUAL",ISNUMBER(SEARCH("INDIVIDUAL",SUBSTITUTE(UPPER($D3)," ","")))),"PREMIUM FREE",""))))
A4: TELA | B4: 52236 | C4: 1RU51 | D4: BANCO SANTANDER BRASIL SA | E4: 11278282823 | F4: 1RU51000204005 | G4: 609.4 | H4: 164.43 | I4: CONTRATUAL | J4: 42063134820 | K4: JULIO ANTONIO VEIGA SERRASQUEIRO | L4: SÃO PAULO | M4: SP | N4: SERGIANA | O4: 519599 | P4: 46020 | Q4: 46021 | R4: AUTORIZADO PAGAMENTO | S4: 8202610642 | T4: 5 DIAS ÚTEIS | U4: 46015 | V4: 46027 | W4: 46034 | X4: 46031 | Y4: =IF(AND(X4<>"",W4<>""),IF(X4<=W4,"SIM","NÃO"),"") | AC4: =IF($C4="","",IF(COUNTIF('Códigos Santander (ref)'!$A$2:$A$79,$C4)>0,"SANTANDER",IF(COUNTIF('Códigos Itaú (ref)'!$A$2:$A$44,$C4)>0,"ITAU",IF(AND(TRIM(UPPER($I4))="CONTRATUAL",ISNUMBER(SEARCH("INDIVIDUAL",SUBSTITUTE(UPPER($D4)," ","")))),"PREMIUM FREE",""))))
A5: TELA | B5: 52242 | C5: 1RUB1 | D5: F1RST TECNOLOGIA E INOVACAO LTDA | E5: 16384262878 | F5: 1RUB1005723000 | G5: 2850 | H5: 81.66 | I5: CONTRATUAL | J5: 42714999000180 | K5: AFD ODONTOLOGIA LTDA | L5: SÃO PAULO | M5: SP | N5: SERGIANA | O5: JA POSSUI | R5: AUTORIZADO PAGAMENTO | S5: 8202610644 | T5: 5 DIAS ÚTEIS | U5: 46020 | V5: 46027 | W5: 46034 | X5: 46031 | Y5: =IF(AND(X5<>"",W5<>""),IF(X5<=W5,"SIM","NÃO"),"") | AC5: =IF($C5="","",IF(COUNTIF('Códigos Santander (ref)'!$A$2:$A$79,$C5)>0,"SANTANDER",IF(COUNTIF('Códigos Itaú (ref)'!$A$2:$A$44,$C5)>0,"ITAU",IF(AND(TRIM(UPPER($I5))="CONTRATUAL",ISNUMBER(SEARCH("INDIVIDUAL",SUBSTITUTE(UPPER($D5)," ","")))),"PREMIUM FREE",""))))
A6: TELA | B6: 52338 | C6: 1RUB1 | D6: F1RST TECNOLOGIA E INOVACAO LTDA | E6: 35369845840 | F6: 1RUB1002304015 | G6: 175 | H6: 175 | I6: CONTRATUAL | J6: 36897556890 | K6: IINGRID CAROLINE CRUZ BUSSINE | L6: SÃO PAULO | M6: SP | N6: SERGIANA | O6: JA POSSUI | R6: AUTORIZADO PAGAMENTO | S6: 8202610645 | T6: 5 DIAS ÚTEIS | U6: 46020 | V6: 46027 | W6: 46034 | X6: 46031 | Y6: =IF(AND(X6<>"",W6<>""),IF(X6<=W6,"SIM","NÃO"),"") | AC6: =IF($C6="","",IF(COUNTIF('Códigos Santander (ref)'!$A$2:$A$79,$C6)>0,"SANTANDER",IF(COUNTIF('Códigos Itaú (ref)'!$A$2:$A$44,$C6)>0,"ITAU",IF(AND(TRIM(UPPER($I6))="CONTRATUAL",ISNUMBER(SEARCH("INDIVIDUAL",SUBSTITUTE(UPPER($D6)," ","")))),"PREMIUM FREE",""))))
A7: TELA | B7: 52449 | C7: 1RUH3 | D7: BANCO SANTANDER BRASIL SA | E7: 35294731894 | F7: 1RUH3003838030 | G7: 250 | H7: 212.19 | I7: CONTRATUAL | J7: 21621700860 | K7: CAMILA CRISTINA FANTI TAPIA | L7: SÃO PAULO | M7: SP | N7: SERGIANA | O7: JA POSSUI | R7: AUTORIZADO PAGAMENTO | S7: 8202610646 | T7: 5 DIAS ÚTEIS | U7: 46020 | V7: 46027 | W7: 46034 | X7: 46031 | Y7: =IF(AND(X7<>"",W7<>""),IF(X7<=W7,"SIM","NÃO"),"") | AC7: =IF($C7="","",IF(COUNTIF('Códigos Santander (ref)'!$A$2:$A$79,$C7)>0,"SANTANDER",IF(COUNTIF('Códigos Itaú (ref)'!$A$2:$A$44,$C7)>0,"ITAU",IF(AND(TRIM(UPPER($I7))="CONTRATUAL",ISNUMBER(SEARCH("INDIVIDUAL",SUBSTITUTE(UPPER($D7)," ","")))),"PREMIUM FREE",""))))
A8: TELA | B8: 52525 | C8: 1RUH3 | D8: BANCO SANTANDER BRASIL SA | E8: 25547807818 | F8: 1RUH3021267006 | G8: 350 | H8: 243.88 | I8: CONTRATUAL | J8: 24870458000160 | K8: EDWAL LOBOSCHI | L8: SÃO PAULO | M8: SP | N8: SERGIANA | O8: 520010 | P8: 46027 | Q8: 46027 | R8: AUTORIZADO PAGAMENTO | S8: 8202610772 | T8: 5 DIAS ÚTEIS | U8: 46020 | V8: 46028 | W8: 46035 | X8: 46036 | Y8: =IF(AND(X8<>"",W8<>""),IF(X8<=W8,"SIM","NÃO"),"") | AC8: =IF($C8="","",IF(COUNTIF('Códigos Santander (ref)'!$A$2:$A$79,$C8)>0,"SANTANDER",IF(COUNTIF('Códigos Itaú (ref)'!$A$2:$A$44,$C8)>0,"ITAU",IF(AND(TRIM(UPPER($I8))="CONTRATUAL",ISNUMBER(SEARCH("INDIVIDUAL",SUBSTITUTE(UPPER($D8)," ","")))),"PREMIUM FREE",""))))
A9: TELA | B9: 51651 | C9: 1RUH3 | D9: BANCO SANTANDER BRASIL SA | E9: 47036900806 | F9: 1RUH3015381005 | G9: 350 | H9: 243.88 | I9: CONTRATUAL | J9: 24870458000160 | K9: EDWAL LOBOSCHI | L9: SÃO PAULO | M9: SP | N9: SERGIANA | O9: 520012 | P9: 46027 | Q9: 46027 | R9: AUTORIZADO PAGAMENTO | S9: 8202610773 | T9: 5 DIAS ÚTEIS | U9: 46022 | V9: 46028 | W9: 46035 | X9: 46036 | Y9: =IF(AND(X9<>"",W9<>""),IF(X9<=W9,"SIM","NÃO"),"") | AC9: =IF($C9="","",IF(COUNTIF('Códigos Santander (ref)'!$A$2:$A$79,$C9)>0,"SANTANDER",IF(COUNTIF('Códigos Itaú (ref)'!$A$2:$A$44,$C9)>0,"ITAU",IF(AND(TRIM(UPPER($I9))="CONTRATUAL",ISNUMBER(SEARCH("INDIVIDUAL",SUBSTITUTE(UPPER($D9)," ","")))),"PREMIUM FREE",""))))
A10: TELA | B10: 52426 | C10: 1RUH3 | D10: BANCO SANTANDER BRASIL SA | E10: 5748915529 | F10: 1RUH3014267012 | G10: 115 | H10: 115 | I10: CONTRATUAL | J10: 9028521000121 | K10: RADIUM UNIDADE DE SERVICOS DE IMAGENS DA FACE LTDA | L10: JUAZEIRO | M10: BA | N10: SERGIANA | O10: JA POSSUI | R10: AUTORIZADO PAGAMENTO | S10: 8202610647 | T10: 5 DIAS ÚTEIS | U10: 46022 | V10: 46027 | W10: 46034 | X10: 46031 | Y10: =IF(AND(X10<>"",W10<>""),IF(X10<=W10,"SIM","NÃO"),"") | AC10: =IF($C10="","",IF(COUNTIF('Códigos Santander (ref)'!$A$2:$A$79,$C10)>0,"SANTANDER",IF(COUNTIF('Códigos Itaú (ref)'!$A$2:$A$44,$C10)>0,"ITAU",IF(AND(TRIM(UPPER($I10))="CONTRATUAL",ISNUMBER(SEARCH("INDIVIDUAL",SUBSTITUTE(UPPER($D10)," ","")))),"PREMIUM FREE",""))))
A11: TELA | B11: 52628 | C11: S21FQ | D11: SANTANDER SERVICOS DIGITAIS BRASIL LTDA | E11: 21400310830 | F11: S21FQ000899020 | G11: 250 | H11: 212.19 | I11: CONTRATUAL | J11: 11186762896 | K11: ANA CLAUDIA GGUIMARAES COSTA | L11: CAMPINAS | M11: SP | N11: SERGIANA | O11: JA POSSUI | R11: AUTORIZADO PAGAMENTO | S11: 8202610720 | T11: 5 DIAS ÚTEIS | U11: 46027 | V11: 46028 | W11: 46035 | X11: 46031 | Y11: =IF(AND(X11<>"",W11<>""),IF(X11<=W11,"SIM","NÃO"),"") | Z11: SIM | AC11: =IF($C11="","",IF(COUNTIF('Códigos Santander (ref)'!$A$2:$A$79,$C11)>0,"SANTANDER",IF(COUNTIF('Códigos Itaú (ref)'!$A$2:$A$44,$C11)>0,"ITAU",IF(AND(TRIM(UPPER($I11))="CONTRATUAL",ISNUMBER(SEARCH("INDIVIDUAL",SUBSTITUTE(UPPER($D11)," ","")))),"PREMIUM FREE",""))))
A12: TELA | B12: 52607 | C12: 1RUD5 | D12: SANTANDER HOLDING IMOBILIARIA SA | E12: 26534957833 | F12: 1RUD5000037010 | G12: 300 | H12: 212.19 | I12: CONTRATUAL | J12: 21315482819 | K12: CRISTINA YUKA HASSUNUMA | L12: SÃO PAULO | M12: SP | N12: SERGIANA | O12: JA POSSUI | R12: AUTORIZADO PAGAMENTO | S12: 8202610722 | T12: 5 DIAS ÚTEIS | U12: 46027 | V12: 46028 | W12: 46035 | X12: 46031 | Y12: =IF(AND(X12<>"",W12<>""),IF(X12<=W12,"SIM","NÃO"),"") | AC12: =IF($C12="","",IF(COUNTIF('Códigos Santander (ref)'!$A$2:$A$79,$C12)>0,"SANTANDER",IF(COUNTIF('Códigos Itaú (ref)'!$A$2:$A$44,$C12)>0,"ITAU",IF(AND(TRIM(UPPER($I12))="CONTRATUAL",ISNUMBER(SEARCH("INDIVIDUAL",SUBSTITUTE(UPPER($D12)," ","")))),"PREMIUM FREE",""))))
A13: TELA | B13: 52626 | C13: 1RUH3 | D13: BANCO SANTANDER BRASIL SA | E13: 15858127819 | F13: 1RUH3030565030 | G13: 370 | H13: 51.03 | I13: CONTRATUAL | J13: 4116655961 | K13: MELINA VITALI DA SILVA MATOS | L13: LONDRINA | M13: PR | N13: SERGIANA | O13: JA POSSUI | R13: AUTORIZADO PAGAMENTO | S13: 8202610723 | T13: 5 DIAS ÚTEIS | U13: 46027 | V13: 46028 | W13: 46035 | X13: 46031 | Y13: =IF(AND(X13<>"",W13<>""),IF(X13<=W13,"SIM","NÃO"),"") | AC13: =IF($C13="","",IF(COUNTIF('Códigos Santander (ref)'!$A$2:$A$79,$C13)>0,"SANTANDER",IF(COUNTIF('Códigos Itaú (ref)'!$A$2:$A$44,$C13)>0,"ITAU",IF(AND(TRIM(UPPER($I13))="CONTRATUAL",ISNUMBER(SEARCH("INDIVIDUAL",SUBSTITUTE(UPPER($D13)," ","")))),"PREMIUM FREE",""))))
A14: TELA | B14: 52241 | C14: 1RUH3 | D14: BANCO SANTANDER BRASIL SA | E14: 1835147771 | F14: 1RUH3030092000 | G14: 4250 | H14: 2849.21 | I14: CONTRATUAL | J14: 1287115748 | K14: JULIO CESAR FERREIRA RODRIGUES | L14: SÃO GONÇALO | M14: RJ | N14: SERGIANA | O14: JA POSSUI | R14: AUTORIZADO PAGAMENTO | S14: 8202610724 | T14: 5 DIAS ÚTEIS | U14: 46027 | V14: 46028 | W14: 46035 | X14: 46031 | Y14: =IF(AND(X14<>"",W14<>""),IF(X14<=W14,"SIM","NÃO"),"") | AC14: =IF($C14="","",IF(COUNTIF('Códigos Santander (ref)'!$A$2:$A$79,$C14)>0,"SANTANDER",IF(COUNTIF('Códigos Itaú (ref)'!$A$2:$A$44,$C14)>0,"ITAU",IF(AND(TRIM(UPPER($I14))="CONTRATUAL",ISNUMBER(SEARCH("INDIVIDUAL",SUBSTITUTE(UPPER($D14)," ","")))),"PREMIUM FREE",""))))
A15: TELA | B15: 52451 | C15: 60300 | D15: INDIVIDUAL | E15: 2528015208 | F15: 60300911953014 | G15: 600 | H15: 53.4 | I15: CONTRATUAL | J15: 30278271000174 | K15: ARTE DO SORRISO ODONTOLOGIA | L15: MANAUS | M15: AM | N15: SERGIANA | O15: JA POSSUI | R15: AUTORIZADO PAGAMENTO | S15: 8202610725 | T15: 30 DIAS CORRIDOS | U15: 46027 | V15: 46028 | W15: 46059 | X15: 46031 | Y15: =IF(AND(X15<>"",W15<>""),IF(X15<=W15,"SIM","NÃO"),"") | AC15: =IF($C15="","",IF(COUNTIF('Códigos Santander (ref)'!$A$2:$A$79,$C15)>0,"SANTANDER",IF(COUNTIF('Códigos Itaú (ref)'!$A$2:$A$44,$C15)>0,"ITAU",IF(AND(TRIM(UPPER($I15))="CONTRATUAL",ISNUMBER(SEARCH("INDIVIDUAL",SUBSTITUTE(UPPER($D15)," ","")))),"PREMIUM FREE",""))))
A16: TELA | B16: 52181 | C16: 50700 | D16: INDIVIDUAL MAISODONTO | E16: 10028584457 | F16: 50700371165007 | G16: 1080 | H16: 79.8 | I16: CONTRATUAL | J16: 5259219406 | K16: KEILA NASCIMENTO VIEIRA GAUDENCIO | L16: CAMPINA GRANDE | M16: PB | N16: SERGIANA | O16: 520317 | P16: 46028 | Q16: 46028 | R16: AUTORIZADO PAGAMENTO | S16: 8202610779 | T16: 30 DIAS CORRIDOS | U16: 46027 | V16: 46028 | W16: 46059 | X16: 46036 | Y16: =IF(AND(X16<>"",W16<>""),IF(X16<=W16,"SIM","NÃO"),"") | AC16: =IF($C16="","",IF(COUNTIF('Códigos Santander (ref)'!$A$2:$A$79,$C16)>0,"SANTANDER",IF(COUNTIF('Códigos Itaú (ref)'!$A$2:$A$44,$C16)>0,"ITAU",IF(AND(TRIM(UPPER($I16))="CONTRATUAL",ISNUMBER(SEARCH("INDIVIDUAL",SUBSTITUTE(UPPER($D16)," ","")))),"PREMIUM FREE",""))))
A17: TELA | B17: 50949 | C17: 1RUH3 | D17: BANCO SANTANDER BRASIL SA | E17: 28475431801 | F17: 1RUH3031318010 | G17: 140 | H17: 71.81 | I17: CONTRATUAL | J17: 24973449000102 | K17: RAFAEL DESSIMONI DELA COLETA ME | L17: SÃO JOSÉ DO RIO PARDO | M17: SP | N17: SERGIANA | O17: 520327 | P17: 46028 | Q17: 46028 | R17: AUTORIZADO PAGAMENTO | S17: 8202610781 | T17: 5 DIAS ÚTEIS | U17: 46027 | V17: 46028 | W17: 46035 | X17: 46036 | Y17: =IF(AND(X17<>"",W17<>""),IF(X17<=W17,"SIM","NÃO"),"") | AC17: =IF($C17="","",IF(COUNTIF('Códigos Santander (ref)'!$A$2:$A$79,$C17)>0,"SANTANDER",IF(COUNTIF('Códigos Itaú (ref)'!$A$2:$A$44,$C17)>0,"ITAU",IF(AND(TRIM(UPPER($I17))="CONTRATUAL",ISNUMBER(SEARCH("INDIVIDUAL",SUBSTITUTE(UPPER($D17)," ","")))),"PREMIUM FREE",""))))
A18: TELA | B18: 51040 | C18: 1RUH3 | D18: BANCO SANTANDER BRASIL SA | E18: 8248767760 | F18: 1RUH3019582013 | G18: 260 | H18: 212.19 | I18: CONTRATUAL | J18: 5950466730 | K18: ZULMA FLORES BLANCO QUEIROZ | L18: SÃO GONÇALO | M18: RJ | N18: SERGIANA | O18: JA POSSUI | R18: AUTORIZADO PAGAMENTO | S18: 8202610726 | T18: 5 DIAS ÚTEIS | U18: 46027 | V18: 46028 | W18: 46035 | X18: 46031 | Y18: =IF(AND(X18<>"",W18<>""),IF(X18<=W18,"SIM","NÃO"),"") | AC18: =IF($C18="","",IF(COUNTIF('Códigos Santander (ref)'!$A$2:$A$79,$C18)>0,"SANTANDER",IF(COUNTIF('Códigos Itaú (ref)'!$A$2:$A$44,$C18)>0,"ITAU",IF(AND(TRIM(UPPER($I18))="CONTRATUAL",ISNUMBER(SEARCH("INDIVIDUAL",SUBSTITUTE(UPPER($D18)," ","")))),"PREMIUM FREE",""))))
A19: TELA | B19: 52146 | C19: 1RUH3 | D19: BANCO SANTANDER BRASIL SA | E19: 8248767760 | F19: 1RUH3019582013 | G19: 260 | H19: 212.19 | I19: CONTRATUAL | J19: 5950466730 | K19: ZULMA FLORES BLANCO QUEIROZ | L19: SÃO GONÇALO | M19: RJ | N19: SERGIANA | O19: JA POSSUI | R19: AUTORIZADO PAGAMENTO | S19: 8202610727 | T19: 5 DIAS ÚTEIS | U19: 46027 | V19: 46028 | W19: 46035 | X19: 46031 | Y19: =IF(AND(X19<>"",W19<>""),IF(X19<=W19,"SIM","NÃO"),"") | AC19: =IF($C19="","",IF(COUNTIF('Códigos Santander (ref)'!$A$2:$A$79,$C19)>0,"SANTANDER",IF(COUNTIF('Códigos Itaú (ref)'!$A$2:$A$44,$C19)>0,"ITAU",IF(AND(TRIM(UPPER($I19))="CONTRATUAL",ISNUMBER(SEARCH("INDIVIDUAL",SUBSTITUTE(UPPER($D19)," ","")))),"PREMIUM FREE",""))))
A20: TELA | B20: 51903 | C20: 1RUH3 | D20: BANCO SANTANDER BRASIL SA | E20: 1498442714 | F20: 1RUH3030007038 | G20: 260 | H20: 212.19 | I20: CONTRATUAL | J20: 229031781 | K20: LEONARDO LIMA BITTENCOURT COSTA | L20: SÃO GONÇALO | M20: RJ | N20: SERGIANA | O20: JA POSSUI | R20: AUTORIZADO PAGAMENTO | S20: 8202610730 | T20: 5 DIAS ÚTEIS | U20: 46027 | V20: 46028 | W20: 46035 | X20: 46031 | Y20: =IF(AND(X20<>"",W20<>""),IF(X20<=W20,"SIM","NÃO"),"") | AC20: =IF($C20="","",IF(COUNTIF('Códigos Santander (ref)'!$A$2:$A$79,$C20)>0,"SANTANDER",IF(COUNTIF('Códigos Itaú (ref)'!$A$2:$A$44,$C20)>0,"ITAU",IF(AND(TRIM(UPPER($I20))="CONTRATUAL",ISNUMBER(SEARCH("INDIVIDUAL",SUBSTITUTE(UPPER($D20)," ","")))),"PREMIUM FREE",""))))
A21: TELA | B21: 52425 | C21: S21FQ | D21: SANTANDER SERVICOS DIGITAIS BRASIL LTDA | E21: 21400310830 | F21: S21FQ000899011 | G21: 250 | H21: 212.19 | I21: CONTRATUAL | J21: 11186762896 | K21: ANA CLAUDIA GUIMARAES COSTA | L21: CAMPINAS | M21: SP | N21: SERGIANA | O21: JA POSSUI | R21: AUTORIZADO PAGAMENTO | S21: 8202610733 | T21: 5 DIAS ÚTEIS | U21: 46027 | V21: 46028 | W21: 46035 | X21: 46031 | Y21: =IF(AND(X21<>"",W21<>""),IF(X21<=W21,"SIM","NÃO"),"") | AC21: =IF($C21="","",IF(COUNTIF('Códigos Santander (ref)'!$A$2:$A$79,$C21)>0,"SANTANDER",IF(COUNTIF('Códigos Itaú (ref)'!$A$2:$A$44,$C21)>0,"ITAU",IF(AND(TRIM(UPPER($I21))="CONTRATUAL",ISNUMBER(SEARCH("INDIVIDUAL",SUBSTITUTE(UPPER($D21)," ","")))),"PREMIUM FREE",""))))
A22: TELA | B22: 52646 | C22: S21FQ | D22: SANTANDER SERVICOS DIGITAIS BRASIL LTDA | E22: 21400310830 | F22: S21FQ000899011 | G22: 250 | H22: 212.19 | I22: CONTRATUAL | J22: 11186762896 | K22: ANA CLAUDIA GUIMARAES COSTA | L22: CAMPINAS | M22: SP | N22: SERGIANA | O22: JA POSSUI | R22: AUTORIZADO PAGAMENTO | S22: 8202610734 | T22: 5 DIAS ÚTEIS | U22: 46027 | V22: 46028 | W22: 46035 | X22: 46031 | Y22: =IF(AND(X22<>"",W22<>""),IF(X22<=W22,"SIM","NÃO"),"") | AC22: =IF($C22="","",IF(COUNTIF('Códigos Santander (ref)'!$A$2:$A$79,$C22)>0,"SANTANDER",IF(COUNTIF('Códigos Itaú (ref)'!$A$2:$A$44,$C22)>0,"ITAU",IF(AND(TRIM(UPPER($I22))="CONTRATUAL",ISNUMBER(SEARCH("INDIVIDUAL",SUBSTITUTE(UPPER($D22)," ","")))),"PREMIUM FREE",""))))
A23: TELA | B23: 52669 | C23: 1RUH3 | D23: BANCO SANTANDER BRASIL SA | E23: 2243809745 | F23: 1RU55000339024 | G23: 260 | H23: 90.94 | I23: CONTRATUAL | J23: 5950466730 | K23: ZULMA FLORES BLANCO QUEIROZ | L23: SÃO GONÇALO | M23: RJ | N23: SERGIANA | O23: JA POSSUI | R23: AUTORIZADO PAGAMENTO | S23: 8202610787 | T23: 5 DIAS ÚTEIS | U23: 46028 | V23: 46028 | W23: 46035 | X23: 46036 | Y23: =IF(AND(X23<>"",W23<>""),IF(X23<=W23,"SIM","NÃO"),"") | AC23: =IF($C23="","",IF(COUNTIF('Códigos Santander (ref)'!$A$2:$A$79,$C23)>0,"SANTANDER",IF(COUNTIF('Códigos Itaú (ref)'!$A$2:$A$44,$C23)>0,"ITAU",IF(AND(TRIM(UPPER($I23))="CONTRATUAL",ISNUMBER(SEARCH("INDIVIDUAL",SUBSTITUTE(UPPER($D23)," ","")))),"PREMIUM FREE",""))))
A24: TELA | B24: 52668 | C24: 1RUH3 | D24: BANCO SANTANDER BRASIL SA | E24: 2243809745 | F24: 1RU55000339016 | G24: 260 | H24: 90.94 | I24: CONTRATUAL | J24: 5950466730 | K24: ZULMA FLORES BLANCO QUEIROZ | L24: SÃO GONÇALO | M24: RJ | N24: SERGIANA | O24: JA POSSUI | R24: AUTORIZADO PAGAMENTO | S24: 8202610789 | T24: 5 DIAS ÚTEIS | U24: 46028 | V24: 46028 | W24: 46035 | X24: 46036 | Y24: =IF(AND(X24<>"",W24<>""),IF(X24<=W24,"SIM","NÃO"),"") | AC24: =IF($C24="","",IF(COUNTIF('Códigos Santander (ref)'!$A$2:$A$79,$C24)>0,"SANTANDER",IF(COUNTIF('Códigos Itaú (ref)'!$A$2:$A$44,$C24)>0,"ITAU",IF(AND(TRIM(UPPER($I24))="CONTRATUAL",ISNUMBER(SEARCH("INDIVIDUAL",SUBSTITUTE(UPPER($D24)," ","")))),"PREMIUM FREE",""))))
A25: TELA | B25: 52705 | C25: 1RSLN | D25: ITAU UNIBANCO SA | E25: 80214789772 | F25: 1RSLN015975002 | G25: 10100 | H25: 6999.98 | I25: CONTRATUAL | J25: 8186777750 | K25: FERNANDO CAMPOS MOREIRA | L25: SÃO GONÇALO | M25: RJ | N25: SERGIANA | O25: JA POSSUI | R25: AUTORIZADO PAGAMENTO | S25: 8202610790 | T25: 5 DIAS ÚTEIS | U25: 46028 | V25: 46028 | W25: 46035 | X25: 46036 | Y25: =IF(AND(X25<>"",W25<>""),IF(X25<=W25,"SIM","NÃO"),"") | AC25: =IF($C25="","",IF(COUNTIF('Códigos Santander (ref)'!$A$2:$A$79,$C25)>0,"SANTANDER",IF(COUNTIF('Códigos Itaú (ref)'!$A$2:$A$44,$C25)>0,"ITAU",IF(AND(TRIM(UPPER($I25))="CONTRATUAL",ISNUMBER(SEARCH("INDIVIDUAL",SUBSTITUTE(UPPER($D25)," ","")))),"PREMIUM FREE",""))))
A26: TELA | B26: 52339 | C26: 1RUH3 | D26: BANCO SANTANDER BRASIL SA | E26: 29459620809 | F26: 1RUH3037701002 | G26: 150 | H26: 9.91 | I26: CONTRATUAL | J26: 24463831000168 | K26: CLINICA RADIOLOGICA DIAGNOSTIC DENTE LTDA | L26: EMBU-GUAÇU | M26: SP | N26: SERGIANA | O26: 520555 | P26: 46028 | Q26: 46029 | R26: AUTORIZADO PAGAMENTO | S26: 8202610809 | T26: 5 DIAS ÚTEIS | U26: 46028 | V26: 46029 | W26: 46036 | X26: 46036 | Y26: =IF(AND(X26<>"",W26<>""),IF(X26<=W26,"SIM","NÃO"),"") | AC26: =IF($C26="","",IF(COUNTIF('Códigos Santander (ref)'!$A$2:$A$79,$C26)>0,"SANTANDER",IF(COUNTIF('Códigos Itaú (ref)'!$A$2:$A$44,$C26)>0,"ITAU",IF(AND(TRIM(UPPER($I26))="CONTRATUAL",ISNUMBER(SEARCH("INDIVIDUAL",SUBSTITUTE(UPPER($D26)," ","")))),"PREMIUM FREE",""))))
A27: TELA | B27: 52174 | C27: 1RSX8 | D27: ITAU UNIBANCO SA | E27: 50361414749 | F27: 1RSX8000316008 | G27: 1550 | H27: 691.99 | I27: CONTRATUAL | J27: 7959716722 | K27: JULIANA VIEGAS SONEGHETI | L27: NITEROI | M27: RJ | N27: SERGIANA | O27: JA POSSUI | R27: AUTORIZADO PAGAMENTO | S27: 8202610791 | T27: 5 DIAS ÚTEIS | U27: 46028 | V27: 46028 | W27: 46035 | X27: 46036 | Y27: =IF(AND(X27<>"",W27<>""),IF(X27<=W27,"SIM","NÃO"),"") | AC27: =IF($C27="","",IF(COUNTIF('Códigos Santander (ref)'!$A$2:$A$79,$C27)>0,"SANTANDER",IF(COUNTIF('Códigos Itaú (ref)'!$A$2:$A$44,$C27)>0,"ITAU",IF(AND(TRIM(UPPER($I27))="CONTRATUAL",ISNUMBER(SEARCH("INDIVIDUAL",SUBSTITUTE(UPPER($D27)," ","")))),"PREMIUM FREE",""))))
A28: SAC | B28: 51910 | C28: 0GE92 | D28: CRUZEIRO DO SUL EDUCACIONAL SA | E28: 10708058663 | F28: 0GE92005427010 | G28: 1500 | H28: 1500 | I28: INSUFICIÊNCIA DE REDE | J28: 59327485000175 | K28: PASTRE ODONTOLOGIA | L28: ANDRADAS | M28: MG | N28: SERGIANA | O28: 520563 | P28: 46028 | Q28: 46029 | R28: AUTORIZADO PAGAMENTO | S28: 8202610811 | T28: 30 DIAS CORRIDOS | U28: 46028 | V28: 46029 | W28: 46067 | X28: 46036 | Y28: =IF(AND(X28<>"",W28<>""),IF(X28<=W28,"SIM","NÃO"),"") | AC28: =IF($C28="","",IF(COUNTIF('Códigos Santander (ref)'!$A$2:$A$79,$C28)>0,"SANTANDER",IF(COUNTIF('Códigos Itaú (ref)'!$A$2:$A$44,$C28)>0,"ITAU",IF(AND(TRIM(UPPER($I28))="CONTRATUAL",ISNUMBER(SEARCH("INDIVIDUAL",SUBSTITUTE(UPPER($D28)," ","")))),"PREMIUM FREE",""))))
A29: TELA | B29: 51867 | C29: 1RSLY | D29: ITAU SEGUROS SA | E29: 62422758720 | F29: 1RSLY000039004 | G29: 430 | H29: 239.99 | I29: CONTRATUAL | J29: 40465008000148 | K29: ALFA ODONTO FACIAL LTDA | L29: CABO FRIO | M29: RJ | N29: SERGIANA | O29: 520607 | P29: 46028 | Q29: 46029 | R29: AUTORIZADO PAGAMENTO | S29: 8202610816 | T29: 5 DIAS ÚTEIS | U29: 46028 | V29: 46029 | W29: 46036 | X29: 46036 | Y29: =IF(AND(X29<>"",W29<>""),IF(X29<=W29,"SIM","NÃO"),"") | AC29: =IF($C29="","",IF(COUNTIF('Códigos Santander (ref)'!$A$2:$A$79,$C29)>0,"SANTANDER",IF(COUNTIF('Códigos Itaú (ref)'!$A$2:$A$44,$C29)>0,"ITAU",IF(AND(TRIM(UPPER($I29))="CONTRATUAL",ISNUMBER(SEARCH("INDIVIDUAL",SUBSTITUTE(UPPER($D29)," ","")))),"PREMIUM FREE",""))))
A30: TELA | B30: 52630 | C30: 1RUH3 | D30: BANCO SANTANDER BRASIL SA | E30: 46992730843 | F30: 1RUH3006876021 | G30: 150 | H30: 150 | I30: CONTRATUAL | J30: 37710114857 | K30: LARISSA SANDY DA SILVA LEITE | L30: CRUZEIRO | M30: SP | N30: SERGIANA | O30: JA POSSUI | R30: AUTORIZADO PAGAMENTO | S30: 8202610840 | T30: 5 DIAS ÚTEIS | U30: 46028 | V30: 46029 | W30: 46036 | X30: 46036 | Y30: =IF(AND(X30<>"",W30<>""),IF(X30<=W30,"SIM","NÃO"),"") | AC30: =IF($C30="","",IF(COUNTIF('Códigos Santander (ref)'!$A$2:$A$79,$C30)>0,"SANTANDER",IF(COUNTIF('Códigos Itaú (ref)'!$A$2:$A$44,$C30)>0,"ITAU",IF(AND(TRIM(UPPER($I30))="CONTRATUAL",ISNUMBER(SEARCH("INDIVIDUAL",SUBSTITUTE(UPPER($D30)," ","")))),"PREMIUM FREE",""))))
A31: TELA | B31: 52685 | C31: 1RUH3 | D31: BANCO SANTANDER BRASIL SA | E31: 4053432138 | F31: 1RUH3010105000 | G31: 260 | H31: 181.88 | I31: CONTRATUAL | J31: 236694111 | K31: CRISTIANE KAMINSK | L31: JUARA | M31: MT | N31: SERGIANA | O31: JA POSSUI | R31: AUTORIZADO PAGAMENTO | S31: 8202610842 | T31: 5 DIAS ÚTEIS | U31: 46029 | V31: 46029 | W31: 46036 | X31: 46036 | Y31: =IF(AND(X31<>"",W31<>""),IF(X31<=W31,"SIM","NÃO"),"") | AC31: =IF($C31="","",IF(COUNTIF('Códigos Santander (ref)'!$A$2:$A$79,$C31)>0,"SANTANDER",IF(COUNTIF('Códigos Itaú (ref)'!$A$2:$A$44,$C31)>0,"ITAU",IF(AND(TRIM(UPPER($I31))="CONTRATUAL",ISNUMBER(SEARCH("INDIVIDUAL",SUBSTITUTE(UPPER($D31)," ","")))),"PREMIUM FREE",""))))
A32: TELA | B32: 52369 | C32: 1RUH3 | D32: BANCO SANTANDER BRASIL SA | E32: 48016311857 | F32: 1RUH3000218006 | G32: 250 | H32: 51.03 | I32: CONTRATUAL | J32: 46682363000155 | K32: AMEISI ODONTOLOGIA LTDA | L32: SÃO PAULO | M32: SP | N32: SERGIANA | O32: 520673 | P32: 46029 | Q32: 46029 | R32: AUTORIZADO PAGAMENTO | S32: 8202610942 | T32: 5 DIAS ÚTEIS | U32: 46029 | V32: 46031 | W32: 46038 | X32: 46036 | Y32: =IF(AND(X32<>"",W32<>""),IF(X32<=W32,"SIM","NÃO"),"") | AC32: =IF($C32="","",IF(COUNTIF('Códigos Santander (ref)'!$A$2:$A$79,$C32)>0,"SANTANDER",IF(COUNTIF('Códigos Itaú (ref)'!$A$2:$A$44,$C32)>0,"ITAU",IF(AND(TRIM(UPPER($I32))="CONTRATUAL",ISNUMBER(SEARCH("INDIVIDUAL",SUBSTITUTE(UPPER($D32)," ","")))),"PREMIUM FREE",""))))
A33: TELA | B33: 52410 | C33: 60300 | D33: INDIVIDUAL | E33: 2573627543 | F33: 60300897827024 | G33: 70 | H33: 7.5 | I33: CONTRATUAL | J33: 1142614581 | K33: JEANE DANTAS DE MENEZES VIANA | L33: ARACAJU | M33: SE | N33: SERGIANA | O33: 520682 | P33: 46029 | Q33: 46030 | R33: AUTORIZADO PAGAMENTO | S33: 8202610885 | T33: 30 DIAS CORRIDOS | U33: 46029 | V33: 46031 | W33: 46062 | X33: 46036 | Y33: =IF(AND(X33<>"",W33<>""),IF(X33<=W33,"SIM","NÃO"),"") | AC33: =IF($C33="","",IF(COUNTIF('Códigos Santander (ref)'!$A$2:$A$79,$C33)>0,"SANTANDER",IF(COUNTIF('Códigos Itaú (ref)'!$A$2:$A$44,$C33)>0,"ITAU",IF(AND(TRIM(UPPER($I33))="CONTRATUAL",ISNUMBER(SEARCH("INDIVIDUAL",SUBSTITUTE(UPPER($D33)," ","")))),"PREMIUM FREE",""))))
A34: TELA | B34: 51664 | C34: 1RUH3 | D34: BANCO SANTANDER BRASIL SA | E34: 33555194801 | F34: 1RUH3036142000 | G34: 450 | H34: 312.27 | I34: CONTRATUAL | J34: 24870458000160 | K34: EDWAL LOBOSCHI | L34: SÃO PAULO | M34: SP | N34: SERGIANA | O34: JA POSSUI | R34: AUTORIZADO PAGAMENTO | S34: 8202610941 | T34: 5 DIAS ÚTEIS | U34: 46029 | V34: 46030 | W34: 46037 | X34: 46036 | Y34: =IF(AND(X34<>"",W34<>""),IF(X34<=W34,"SIM","NÃO"),"") | AC34: =IF($C34="","",IF(COUNTIF('Códigos Santander (ref)'!$A$2:$A$79,$C34)>0,"SANTANDER",IF(COUNTIF('Códigos Itaú (ref)'!$A$2:$A$44,$C34)>0,"ITAU",IF(AND(TRIM(UPPER($I34))="CONTRATUAL",ISNUMBER(SEARCH("INDIVIDUAL",SUBSTITUTE(UPPER($D34)," ","")))),"PREMIUM FREE",""))))
A35: TELA | B35: 52387 | C35: 1RU51 | D35: BANCO SANTANDER BRASIL SA | E35: 3526964866 | F35: 1RU51000389005 | G35: 2120 | H35: 1595.11 | I35: CONTRATUAL | J35: 67069282672 | K35: LEONE RIBEIRO DE ALMEIDA | L35: SÃO PAULO | M35: SP | N35: SERGIANA | O35: JA POSSUI | R35: AUTORIZADO PAGAMENTO | S35: 8202610847 | T35: 5 DIAS ÚTEIS | U35: 46029 | V35: 46029 | W35: 46036 | X35: 46036 | Y35: =IF(AND(X35<>"",W35<>""),IF(X35<=W35,"SIM","NÃO"),"") | AC35: =IF($C35="","",IF(COUNTIF('Códigos Santander (ref)'!$A$2:$A$79,$C35)>0,"SANTANDER",IF(COUNTIF('Códigos Itaú (ref)'!$A$2:$A$44,$C35)>0,"ITAU",IF(AND(TRIM(UPPER($I35))="CONTRATUAL",ISNUMBER(SEARCH("INDIVIDUAL",SUBSTITUTE(UPPER($D35)," ","")))),"PREMIUM FREE",""))))
A36: TELA | B36: 52611 | C36: 1RUH3 | D36: BANCO SANTANDER BRASIL SA | E36: 14580526805 | F36: 1RUH3030679036 | G36: 180 | H36: 124.6 | I36: CONTRATUAL | J36: 27364022864 | K36: ANA CAROLINA RIZZO | L36: BOTUCATU | M36: SP | N36: SERGIANA | O36: JA POSSUI | R36: AUTORIZADO PAGAMENTO | S36: 8202610848 | T36: 5 DIAS ÚTEIS | U36: 46029 | V36: 46029 | W36: 46036 | X36: 46036 | Y36: =IF(AND(X36<>"",W36<>""),IF(X36<=W36,"SIM","NÃO"),"") | AC36: =IF($C36="","",IF(COUNTIF('Códigos Santander (ref)'!$A$2:$A$79,$C36)>0,"SANTANDER",IF(COUNTIF('Códigos Itaú (ref)'!$A$2:$A$44,$C36)>0,"ITAU",IF(AND(TRIM(UPPER($I36))="CONTRATUAL",ISNUMBER(SEARCH("INDIVIDUAL",SUBSTITUTE(UPPER($D36)," ","")))),"PREMIUM FREE",""))))
A37: TELA | B37: 52765 | C37: 1RUH3 | D37: BANCO SANTANDER BRASIL SA | E37: 2635116776 | F37: 1RUH3032448023 | G37: 730 | H37: 397.34 | I37: CONTRATUAL | J37: 5187127705 | K37: LUCINDA MERCEDES CORDEIRO DE VASCONCELOS OLIVEIRA | L37: SÃO GONÇALO | M37: RJ | N37: SERGIANA | O37: JA POSSUI | R37: AUTORIZADO PAGAMENTO | S37: 8202610918 | T37: 5 DIAS ÚTEIS | U37: 46029 | V37: 46030 | W37: 46037 | X37: 46036 | Y37: =IF(AND(X37<>"",W37<>""),IF(X37<=W37,"SIM","NÃO"),"") | AC37: =IF($C37="","",IF(COUNTIF('Códigos Santander (ref)'!$A$2:$A$79,$C37)>0,"SANTANDER",IF(COUNTIF('Códigos Itaú (ref)'!$A$2:$A$44,$C37)>0,"ITAU",IF(AND(TRIM(UPPER($I37))="CONTRATUAL",ISNUMBER(SEARCH("INDIVIDUAL",SUBSTITUTE(UPPER($D37)," ","")))),"PREMIUM FREE",""))))
A38: TELA | B38: 52613 | C38: 1RUH3 | D38: BANCO SANTANDER BRASIL SA | E38: 26447218811 | F38: 1RUH3032093004 | G38: 200 | H38: 200 | I38: CONTRATUAL | J38: 5389120000146 | K38: K N SERVICOS MEDICOS E ODONTOLOGICOS S/S LTDA | L38: JACAREÍ | M38: SP | N38: SERGIANA | O38: JA POSSUI | R38: AUTORIZADO PAGAMENTO | S38: 8202610919 | T38: 5 DIAS ÚTEIS | U38: 46029 | V38: 46030 | W38: 46037 | X38: 46036 | Y38: =IF(AND(X38<>"",W38<>""),IF(X38<=W38,"SIM","NÃO"),"") | AC38: =IF($C38="","",IF(COUNTIF('Códigos Santander (ref)'!$A$2:$A$79,$C38)>0,"SANTANDER",IF(COUNTIF('Códigos Itaú (ref)'!$A$2:$A$44,$C38)>0,"ITAU",IF(AND(TRIM(UPPER($I38))="CONTRATUAL",ISNUMBER(SEARCH("INDIVIDUAL",SUBSTITUTE(UPPER($D38)," ","")))),"PREMIUM FREE",""))))
A39: TELA | B39: 51385 | C39: 1RSLN | D39: ITAU UNIBANCO SA | E39: 710685700 | F39: 1RSLN018578004 | G39: 1200 | H39: 1200 | I39: CONTRATUAL | J39: 11564355799 | K39: PILLAR CORREA SILVA SARDINHA | L39: CAMPO DOS GOYTACAZES | M39: RJ | N39: SERGIANA | O39: 520940 | P39: 46030 | Q39: 46030 | R39: AUTORIZADO PAGAMENTO | S39: 8202610922 | T39: 5 DIAS ÚTEIS | U39: 46030 | V39: 46030 | W39: 46037 | X39: 46036 | Y39: =IF(AND(X39<>"",W39<>""),IF(X39<=W39,"SIM","NÃO"),"") | AC39: =IF($C39="","",IF(COUNTIF('Códigos Santander (ref)'!$A$2:$A$79,$C39)>0,"SANTANDER",IF(COUNTIF('Códigos Itaú (ref)'!$A$2:$A$44,$C39)>0,"ITAU",IF(AND(TRIM(UPPER($I39))="CONTRATUAL",ISNUMBER(SEARCH("INDIVIDUAL",SUBSTITUTE(UPPER($D39)," ","")))),"PREMIUM FREE",""))))
A40: NIP | B40: 52687 | C40: WXJ2I | D40: HC CONSULTORIA EM GESTAO EMPRESARIAL E AMBIENTAL LTDA | E40: 335513247 | F40: WXJ2I000025003 | G40: 180 | H40: 180 | I40: COBRANÇA INDEVIDA | J40: 32884766000172 | K40: KELLY LEOPOLDINA SOARES FILGUEIRAS COSTA | L40: MANAUS | M40: AM | N40: CIBELY | O40: 520976 | P40: 46030 | Q40: 46030 | R40: AUTORIZADO PAGAMENTO | S40: 8202610923 | T40: 30 DIAS CORRIDOS | U40: 46030 | V40: 46030 | W40: 46061 | X40: 46036 | Y40: =IF(AND(X40<>"",W40<>""),IF(X40<=W40,"SIM","NÃO"),"") | AC40: =IF($C40="","",IF(COUNTIF('Códigos Santander (ref)'!$A$2:$A$79,$C40)>0,"SANTANDER",IF(COUNTIF('Códigos Itaú (ref)'!$A$2:$A$44,$C40)>0,"ITAU",IF(AND(TRIM(UPPER($I40))="CONTRATUAL",ISNUMBER(SEARCH("INDIVIDUAL",SUBSTITUTE(UPPER($D40)," ","")))),"PREMIUM FREE",""))))
...

Sheet Fevereiro 2026
A1: CANAL | B1: N° SOLICITAÇÃO | C1: CÓD. EMPRESA | D1: EMPRESA | E1: CPF TITULAR | F1: COD. DO BENEFICIÁRIO | G1: VALOR SOLICITADO | H1: VALOR PAGO | I1: MOTIVO | J1: CPF/CNPJ DENTISTA | K1: NOME PRESTADOR DE SERVIÇO | L1: CIDADE PRESTADOR | M1: UF PRESTADOR | N1: AUDITOR | O1: ASTREIN | P1: DT SOLICITAÇÃO ASTREIN | Q1: DT LIBERAÇÃO ASTREIN | R1: STATUS DA SOLICITAÇÃO | S1: PROCESSO | T1: PRAZO CONTRATUAL | U1: DT AUDITORIA | V1: DT APROVAÇÃO | W1: DT PRAZO CONTRATUAL | X1: DATA DE PAGAMENTO SAP | Y1: PRAZO ATENDIDO | Z1: OBS | AC1: SEGMENTO (auxiliar automático)
A2: TELA | B2: 53289 | C2: 1RUH3 | D2: BANCO SANTANDER BRASIL SA | E2: 27277126858 | F2: 1RUH3014749009 | G2: 350 | H2: 243.88 | I2: CONTRATUAL | J2: 24870458000160 | K2: EDWAL LOBOSCHI | L2: SÃO PAULO | M2: SP | N2: SERGIANA | O2: JA POSSUI | R2: AUTORIZADO PAGAMENTO | S2: 8202617774 | T2: 5 DIAS ÚTEIS | U2: 46052 | V2: 46055 | W2: 46062 | X2: 46059 | Y2: =IF(AND(X2<>"",W2<>""),IF(X2<=W2,"SIM","NÃO"),"") | AC2: =IF($C2="","",IF(COUNTIF('Códigos Santander (ref)'!$A$2:$A$79,$C2)>0,"SANTANDER",IF(COUNTIF('Códigos Itaú (ref)'!$A$2:$A$44,$C2)>0,"ITAU",IF(AND(TRIM(UPPER($I2))="CONTRATUAL",ISNUMBER(SEARCH("INDIVIDUAL",SUBSTITUTE(UPPER($D2)," ","")))),"PREMIUM FREE",""))))
A3: TELA | B3: 53186 | C3: 1RU51 | D3: BANCO SANTANDER BRASIL SA | E3: 764153846 | F3: 1RU51000760005 | G3: 140 | H3: 140 | I3: CONTRATUAL | J3: 2190751000143 | K3: UNIRAD SERVICOS ODONTOLOGICOS LTDA | L3: SÃO PAULO | M3: SP | N3: SERGIANA | O3: JA POSSUI | R3: AUTORIZADO PAGAMENTO | S3: 8202617776 | T3: 5 DIAS ÚTEIS | U3: 46052 | V3: 46055 | W3: 46062 | X3: 46059 | Y3: =IF(AND(X3<>"",W3<>""),IF(X3<=W3,"SIM","NÃO"),"") | AC3: =IF($C3="","",IF(COUNTIF('Códigos Santander (ref)'!$A$2:$A$79,$C3)>0,"SANTANDER",IF(COUNTIF('Códigos Itaú (ref)'!$A$2:$A$44,$C3)>0,"ITAU",IF(AND(TRIM(UPPER($I3))="CONTRATUAL",ISNUMBER(SEARCH("INDIVIDUAL",SUBSTITUTE(UPPER($D3)," ","")))),"PREMIUM FREE",""))))
A4: TELA | B4: 51889 | C4: 1RUH3 | D4: BANCO SANTANDER BRASIL SA | E4: 26501291828 | F4: 1RUH3030923000 | G4: 360 | H4: 243.88 | I4: CONTRATUAL | J4: 15739539897 | K4: MARCIA REGINA DE OLIVEIRA FARINA | L4: SÃO PAULO | M4: SP | N4: SERGIANA | O4: 526826 | P4: 46052 | Q4: 46055 | R4: AUTORIZADO PAGAMENTO | S4: 8202617873 | T4: 5 DIAS ÚTEIS | U4: 46051 | V4: 46056 | W4: 46063 | X4: 46062 | Y4: =IF(AND(X4<>"",W4<>""),IF(X4<=W4,"SIM","NÃO"),"") | AC4: =IF($C4="","",IF(COUNTIF('Códigos Santander (ref)'!$A$2:$A$79,$C4)>0,"SANTANDER",IF(COUNTIF('Códigos Itaú (ref)'!$A$2:$A$44,$C4)>0,"ITAU",IF(AND(TRIM(UPPER($I4))="CONTRATUAL",ISNUMBER(SEARCH("INDIVIDUAL",SUBSTITUTE(UPPER($D4)," ","")))),"PREMIUM FREE",""))))
A5: TELA | B5: 51965 | C5: 1RUH3 | D5: BANCO SANTANDER BRASIL SA | E5: 26501291828 | F5: 1RUH3030923018 | G5: 360 | H5: 243.88 | I5: CONTRATUAL | J5: 15739539897 | K5: MARCIA REGINA DE OLIVEIRA FARINA | L5: SÃO PAULO | M5: SP | N5: SERGIANA | O5: 526826 | P5: 46052 | Q5: 46055 | R5: AUTORIZADO PAGAMENTO | S5: 8202617874 | T5: 5 DIAS ÚTEIS | U5: 46051 | V5: 46056 | W5: 46063 | X5: 46057 | Y5: =IF(AND(X5<>"",W5<>""),IF(X5<=W5,"SIM","NÃO"),"") | AC5: =IF($C5="","",IF(COUNTIF('Códigos Santander (ref)'!$A$2:$A$79,$C5)>0,"SANTANDER",IF(COUNTIF('Códigos Itaú (ref)'!$A$2:$A$44,$C5)>0,"ITAU",IF(AND(TRIM(UPPER($I5))="CONTRATUAL",ISNUMBER(SEARCH("INDIVIDUAL",SUBSTITUTE(UPPER($D5)," ","")))),"PREMIUM FREE",""))))
A6: TELA | B6: 51780 | C6: 1RUH3 | D6: BANCO SANTANDER BRASIL SA | E6: 26501291828 | F6: 1RUH3030923026 | G6: 360 | H6: 173.51 | I6: CONTRATUAL | J6: 15739539897 | K6: MARCIA REGINA DE OLIVEIRA FARINA | L6: SÃO PAULO | M6: SP | N6: SERGIANA | O6: 526826 | P6: 46052 | Q6: 46055 | R6: AUTORIZADO PAGAMENTO | S6: 8202617875 | T6: 5 DIAS ÚTEIS | U6: 46051 | V6: 46056 | W6: 46063 | X6: 46057 | Y6: =IF(AND(X6<>"",W6<>""),IF(X6<=W6,"SIM","NÃO"),"") | AC6: =IF($C6="","",IF(COUNTIF('Códigos Santander (ref)'!$A$2:$A$79,$C6)>0,"SANTANDER",IF(COUNTIF('Códigos Itaú (ref)'!$A$2:$A$44,$C6)>0,"ITAU",IF(AND(TRIM(UPPER($I6))="CONTRATUAL",ISNUMBER(SEARCH("INDIVIDUAL",SUBSTITUTE(UPPER($D6)," ","")))),"PREMIUM FREE",""))))
A7: SAC | B7: 53143 | C7: 0JMJX | D7: MARIA JEUSA DO NASCIMENTO ALMEIDA | E7: 15183274860 | F7: 0JMJX472647011 | G7: 300 | H7: 300 | I7: INSUFICIÊNCIA DE REDE | J7: 59527440000144 | K7: UNIODONTO DE JUNDIAI-COOPERATIVA ODONTOLOGICA | L7: JUNDIAÍ | M7: SP | N7: SERGIANA | O7: 526730 | P7: 46052 | Q7: 46055 | R7: AUTORIZADO PAGAMENTO | S7: 8202617772 | T7: 30 DIAS CORRIDOS | U7: 46051 | V7: 46055 | W7: 46083 | X7: 46057 | Y7: =IF(AND(X7<>"",W7<>""),IF(X7<=W7,"SIM","NÃO"),"") | AC7: =IF($C7="","",IF(COUNTIF('Códigos Santander (ref)'!$A$2:$A$79,$C7)>0,"SANTANDER",IF(COUNTIF('Códigos Itaú (ref)'!$A$2:$A$44,$C7)>0,"ITAU",IF(AND(TRIM(UPPER($I7))="CONTRATUAL",ISNUMBER(SEARCH("INDIVIDUAL",SUBSTITUTE(UPPER($D7)," ","")))),"PREMIUM FREE",""))))
A8: TELA | B8: 53289 | C8: 1RUH3 | D8: BANCO SANTANDER BRASIL SA | E8: 27277126858 | F8: 1RUH3014749009 | G8: 350 | H8: 243.88 | I8: CONTRATUAL | J8: 24870458000160 | K8: EDWAL LOBOSCHI | L8: SÃO PAULO | M8: SP | N8: SERGIANA | O8: JA POSSUI | R8: AUTORIZADO PAGAMENTO | S8: 8202617774 | T8: 5 DIAS ÚTEIS | U8: 46052 | V8: 46055 | W8: 46062 | X8: 46059 | Y8: =IF(AND(X8<>"",W8<>""),IF(X8<=W8,"SIM","NÃO"),"") | AC8: =IF($C8="","",IF(COUNTIF('Códigos Santander (ref)'!$A$2:$A$79,$C8)>0,"SANTANDER",IF(COUNTIF('Códigos Itaú (ref)'!$A$2:$A$44,$C8)>0,"ITAU",IF(AND(TRIM(UPPER($I8))="CONTRATUAL",ISNUMBER(SEARCH("INDIVIDUAL",SUBSTITUTE(UPPER($D8)," ","")))),"PREMIUM FREE",""))))
A9: TELA | B9: 53186 | C9: 1RU51 | D9: BANCO SANTANDER BRASIL SA | E9: 764153846 | F9: 1RU51000760005 | G9: 140 | H9: 140 | I9: CONTRATUAL | J9: 2190751000143 | K9: UNIRAD SERVICOS ODONTOLOGICOS LTDA | L9: SÃO PAULO | M9: SP | N9: SERGIANA | O9: JA POSSUI | R9: AUTORIZADO PAGAMENTO | S9: 8202617776 | T9: 5 DIAS ÚTEIS | U9: 46052 | V9: 46055 | W9: 46062 | X9: 46059 | Y9: =IF(AND(X9<>"",W9<>""),IF(X9<=W9,"SIM","NÃO"),"") | AC9: =IF($C9="","",IF(COUNTIF('Códigos Santander (ref)'!$A$2:$A$79,$C9)>0,"SANTANDER",IF(COUNTIF('Códigos Itaú (ref)'!$A$2:$A$44,$C9)>0,"ITAU",IF(AND(TRIM(UPPER($I9))="CONTRATUAL",ISNUMBER(SEARCH("INDIVIDUAL",SUBSTITUTE(UPPER($D9)," ","")))),"PREMIUM FREE",""))))
A10: TELA | B10: 53280 | C10: 1RUB1 | D10: F1RST TECNOLOGIA E INOVACAO LTDA | E10: 16240400807 | F10: 1RUB1000530000 | G10: 908 | H10: 243.88 | I10: CONTRATUAL | J10: 2627303163 | K10: LAURA GUIMARAES MELO COSTA | L10: SANTOS | M10: SP | N10: SERGIANA | O10: 527566 | P10: 46056 | Q10: 46057 | R10: AUTORIZADO PAGAMENTO | S10: 8202617965 | T10: 5 DIAS ÚTEIS | U10: 46056 | V10: 46058 | W10: 46065 | X10: 46064 | Y10: SIM | AC10: =IF($C10="","",IF(COUNTIF('Códigos Santander (ref)'!$A$2:$A$79,$C10)>0,"SANTANDER",IF(COUNTIF('Códigos Itaú (ref)'!$A$2:$A$44,$C10)>0,"ITAU",IF(AND(TRIM(UPPER($I10))="CONTRATUAL",ISNUMBER(SEARCH("INDIVIDUAL",SUBSTITUTE(UPPER($D10)," ","")))),"PREMIUM FREE",""))))
A11: TELA | B11: 53293 | C11: 1RUD5 | D11: SANTANDER HOLDING IMOBILIARIA SA | E11: 26534957833 | F11: 1RUD5000037010 | G11: 300 | H11: 212.19 | I11: CONTRATUAL | J11: 21315482819 | K11: CRISTINA YUKA HASSUNUMA | L11: SÃO PAULO | M11: SP | N11: SERGIANA | O11: JA POSSUI | R11: AUTORIZADO PAGAMENTO | S11: 8202617888 | T11: 5 DIAS ÚTEIS | U11: 46056 | V11: 46056 | W11: 46063 | X11: 46062 | Y11: SIM | AC11: =IF($C11="","",IF(COUNTIF('Códigos Santander (ref)'!$A$2:$A$79,$C11)>0,"SANTANDER",IF(COUNTIF('Códigos Itaú (ref)'!$A$2:$A$44,$C11)>0,"ITAU",IF(AND(TRIM(UPPER($I11))="CONTRATUAL",ISNUMBER(SEARCH("INDIVIDUAL",SUBSTITUTE(UPPER($D11)," ","")))),"PREMIUM FREE",""))))
A12: TELA | B12: 53331 | C12: 1RUH3 | D12: BANCO SANTANDER BRASIL SA | E12: 46992730843 | F12: 1RUH3006876021 | G12: 150 | H12: 150 | I12: CONTRATUAL | J12: 37710114857 | K12: LARISSA SANDY DA SILVA LEITE | L12: CRUZEIRO | M12: SP | N12: SERGIANA | O12: JA POSSUI | R12: AUTORIZADO PAGAMENTO | S12: 8202617889 | T12: 5 DIAS ÚTEIS | U12: 46056 | V12: 46056 | W12: 46063 | X12: 46062 | Y12: SIM | AC12: =IF($C12="","",IF(COUNTIF('Códigos Santander (ref)'!$A$2:$A$79,$C12)>0,"SANTANDER",IF(COUNTIF('Códigos Itaú (ref)'!$A$2:$A$44,$C12)>0,"ITAU",IF(AND(TRIM(UPPER($I12))="CONTRATUAL",ISNUMBER(SEARCH("INDIVIDUAL",SUBSTITUTE(UPPER($D12)," ","")))),"PREMIUM FREE",""))))
A13: TELA | B13: 48305 | C13: 1RSX8 | D13: ITAU UNIBANCO SA | E13: 73126810772 | F13: 1RSX8000317012 | G13: 4490 | H13: 931 | I13: CONTRATUAL | J13: 7959716722 | K13: JULIANA VIEGAS SONEGHETI | L13: NITERÓI | M13: RJ | N13: SERGIANA | O13: JA POSSUI | R13: AUTORIZADO PAGAMENTO | S13: 8202617890 | T13: 5 DIAS ÚTEIS | U13: 46056 | V13: 46056 | W13: 46063 | X13: 46062 | Y13: SIM | AC13: =IF($C13="","",IF(COUNTIF('Códigos Santander (ref)'!$A$2:$A$79,$C13)>0,"SANTANDER",IF(COUNTIF('Códigos Itaú (ref)'!$A$2:$A$44,$C13)>0,"ITAU",IF(AND(TRIM(UPPER($I13))="CONTRATUAL",ISNUMBER(SEARCH("INDIVIDUAL",SUBSTITUTE(UPPER($D13)," ","")))),"PREMIUM FREE",""))))
A14: TELA | B14: 46747 | C14: 1RUH3 | D14: BANCO SANTANDER BRASIL SA | E14: 40072933844 | F14: 1RUH3038441004 | G14: 3200 | H14: 470.25 | I14: CONTRATUAL | J14: 30589069861 | K14: SILVIO A. T. MACHADO FILHO | L14: SÃO PAULO | M14: SP | N14: SERGIANA | O14: 527568 | P14: 46056 | Q14: 46062 | R14: AUTORIZADO PAGAMENTO | S14: 8202618173 | T14: 5 DIAS ÚTEIS | U14: 46056 | V14: 46062 | W14: 46069 | X14: 46071 | Y14: NÃO | AC14: =IF($C14="","",IF(COUNTIF('Códigos Santander (ref)'!$A$2:$A$79,$C14)>0,"SANTANDER",IF(COUNTIF('Códigos Itaú (ref)'!$A$2:$A$44,$C14)>0,"ITAU",IF(AND(TRIM(UPPER($I14))="CONTRATUAL",ISNUMBER(SEARCH("INDIVIDUAL",SUBSTITUTE(UPPER($D14)," ","")))),"PREMIUM FREE",""))))
A15: TELA | B15: 53290 | C15: 1RUH3 | D15: BANCO SANTANDER BRASIL SA | E15: 22024640850 | F15: 1RUH3033793018 | G15: 352.06 | H15: 352.06 | I15: CONTRATUAL | J15: 5671101000108 | K15: FORMMA ODONTO LTDA | L15: SÃO PAULO | M15: SP | N15: SERGIANA | O15: JA POSSUI | R15: AUTORIZADO PAGAMENTO | S15: 8202617891 | T15: 5 DIAS ÚTEIS | U15: 46056 | V15: 46056 | W15: 46063 | X15: 46062 | Y15: SIM | AC15: =IF($C15="","",IF(COUNTIF('Códigos Santander (ref)'!$A$2:$A$79,$C15)>0,"SANTANDER",IF(COUNTIF('Códigos Itaú (ref)'!$A$2:$A$44,$C15)>0,"ITAU",IF(AND(TRIM(UPPER($I15))="CONTRATUAL",ISNUMBER(SEARCH("INDIVIDUAL",SUBSTITUTE(UPPER($D15)," ","")))),"PREMIUM FREE",""))))
A16: TELA | B16: 53225 | C16: 1RU51 | D16: BANCO SANTANDER BRASIL SA | E16: 21957476842 | F16: 1RU51000355011 | G16: 210 | H16: 90.94 | I16: CONTRATUAL | J16: 8229165000141 | K16: CLINICA NEW LIFE PRIME ODONTOLOGIA LTDA | L16: SÃO PAULO | M16: SP | N16: SERGIANA | O16: JA POSSUI | R16: AUTORIZADO PAGAMENTO | S16: 8202617892 | T16: 5 DIAS ÚTEIS | U16: 46056 | V16: 46056 | W16: 46063 | X16: 46062 | Y16: SIM | AC16: =IF($C16="","",IF(COUNTIF('Códigos Santander (ref)'!$A$2:$A$79,$C16)>0,"SANTANDER",IF(COUNTIF('Códigos Itaú (ref)'!$A$2:$A$44,$C16)>0,"ITAU",IF(AND(TRIM(UPPER($I16))="CONTRATUAL",ISNUMBER(SEARCH("INDIVIDUAL",SUBSTITUTE(UPPER($D16)," ","")))),"PREMIUM FREE",""))))
A17: TELA | B17: 53189 | C17: 1RBB2 | D17: PROTEGE SA PROTECAO E TRANSPORTE DE VALORES | E17: 7054095626 | F17: 1RBB2000304000 | G17: 55 | H17: 55 | I17: COBRANÇA INDEVIDA | J17: 29727662000140 | K17: ODONTOMED CONSULTORIO E SERVICOS LTDA | L17: MURIAÉ | M17: MG | N17: SERGIANA | O17: 527569 | P17: 46056 | Q17: 46063 | R17: AUTORIZADO PAGAMENTO | S17: 8202618221 | T17: 30 DIAS CORRIDOS | U17: 46056 | V17: 46063 | W17: 46091 | X17: 46071 | Y17: SIM | AC17: =IF($C17="","",IF(COUNTIF('Códigos Santander (ref)'!$A$2:$A$79,$C17)>0,"SANTANDER",IF(COUNTIF('Códigos Itaú (ref)'!$A$2:$A$44,$C17)>0,"ITAU",IF(AND(TRIM(UPPER($I17))="CONTRATUAL",ISNUMBER(SEARCH("INDIVIDUAL",SUBSTITUTE(UPPER($D17)," ","")))),"PREMIUM FREE",""))))
A18: TELA | B18: 53247 | C18: 1RBB2 | D18: PROTEGE SA PROTECAO E TRANSPORTE DE VALORES | E18: 7054095626 | F18: 1RBB2000304000 | G18: 50 | H18: 20 | I18: INSUFICIÊNCIA DE REDE | J18: 58148715000176 | K18: RXT RADIOLOGIA ODONTOLOGICA LTDA | L18: MURIAÉ | M18: MG | N18: SERGIANA | O18: 527569 | P18: 46056 | Q18: 46063 | R18: AUTORIZADO PAGAMENTO | S18: 8202618222 | T18: 30 DIAS CORRIDOS | U18: 46056 | V18: 46063 | W18: 46091 | X18: 46071 | Y18: SIM | AC18: =IF($C18="","",IF(COUNTIF('Códigos Santander (ref)'!$A$2:$A$79,$C18)>0,"SANTANDER",IF(COUNTIF('Códigos Itaú (ref)'!$A$2:$A$44,$C18)>0,"ITAU",IF(AND(TRIM(UPPER($I18))="CONTRATUAL",ISNUMBER(SEARCH("INDIVIDUAL",SUBSTITUTE(UPPER($D18)," ","")))),"PREMIUM FREE",""))))
